Workbook

Sheet partidos regular
A1: partidos jugados | B1: 107
A2: Temporada
A3: Regular
A6: AE | B6: 2019-1
A7: SJ
A8: LP
A9: NG
A10: ES | B10: 2
A11: JL
A12: NP
A13: GA
A14: EJ | B14: 3
A15: LN
A16: GS
A17: GE | B17: 4
A18: JN
A19: LA
A20: JG | B20: 5
A21: NA
A22: LS
A23: EL | B23: 6
A24: GP
A25: AJ
A26: SN
A27: NE | B27: 7
A28: AS
A29: GL
A30: EA | B30: 8
A31: LP
A32: SJ
A33: GN
A34: ES | B34: 9
A35: LJ
A36: GA
A37: EJ | B37: 10
A38: LN
A39: AP
A40: GS
A41: EG | B41: 11
A42: NJ
...

Sheet playoffs
A1: P | B1: 1-2 | C1: 3-4 | D1: 7-8 | E1: F
A5: LG | B5: E | C5: G | D5: S | E5: LP | H5: P= semis de playoffs | J5: despues posiciones temporada regular
B6: L | D6: J | E6: GJ | J6: final en la F
A7: GN | B7: G | C7: J | D7: S | E7: SL
A8: JE | B8: E | C8: N | D8: C | E8: EK | H8: 2025 | I8: : ultimo bloque
A9: LJ | B9: J | C9: S | D9: N | E9: JN
A10: SE | B10: E | C10: L | D10: G | E10: LJ
A11: EJ | B11: J | C11: N | D11: G | E11: JG
A12: KN | B12: K | C12: E | D12: L
A13: NC | B13: N | C13: J | D13: G
A14: JS | B14: S | C14: C | D14: E
A15: JG | B15: J | C15: S | D15: E
A16: LS | B16: L | C16: G | D16: K
A17: GS | B17: G | C17: L | D17: E
A18: JL | B18: J | C18: S | D18: K

Sheet stats
A1: Emily
A2: Victorias | B2: =COUNTIF('partidos regular'!A:A,"E*") -> 56
A3: Win Rate | B3: =(B2/'partidos regular'!$B$1)*100 -> 52.336449
A4: Puntos totales | B4: =SUM(B6:B13) -> 13899.02
A5: Point rate | B5: =B4/'partidos regular'!$B$1 -> 129.89738
A6: Puntos 2019 | B6: 1704.78
A7: Puntos 2020 | B7: 1814.88
A8: Puntos 2021 | B8: 1970.04
A9: Puntos 2022 | B9: 2047.52
A10: Puntos 2023 | B10: 1873.52
A11: Puntos 2024 | B11: 1812.42
A12: Puntos 2025 | B12: 1744.1
A13: Puntos 2026 | B13: 931.76
A14: Juany
A15: Victorias | B15: =COUNTIF('partidos regular'!A:A,"J*") -> 64
A16: Win Rate | B16: =(B15/'partidos regular'!$B$1)*100 -> 59.813084
A17: Puntos totales | B17: =SUM(B19:B26) -> 14836.82
A18: Point rate | B18: =B17/'partidos regular'!$B$1 -> 138.66187
A19: Puntos 2019 | B19: 1501.6
A20: Puntos 2020 | B20: 1769.2
A21: Puntos 2021 | B21: 2237
A22: Puntos 2022 | B22: 2036.44
A23: Puntos 2023 | B23: 2083.06
A24: Puntos 2024 | B24: 2223.02
A25: Puntos 2025 | B25: 2216.42
A26: Puntos 2026 | B26: 770.08
A27: Latuf
A28: Victorias | B28: =COUNTIF('partidos regular'!A:A,"L*") -> 52
A29: Win Rate | B29: =(B28/'partidos regular'!$B$1)*100 -> 48.598131
A30: Puntos totales | B30: =SUM(B32:B39) -> 13844.92
A31: Point rate | B31: =B30/'partidos regular'!$B$1 -> 129.39178
A32: Puntos 2019 | B32: 1757.1
A33: Puntos 2020 | B33: 1815.4
A34: Puntos 2021 | B34: 1899.86
A35: Puntos 2022 | B35: 1750.04
A36: Puntos 2023 | B36: 1860.94
A37: Puntos 2024 | B37: 2079.48
A38: Puntos 2025 | B38: 2032.1
A39: Puntos 2026 | B39: 650
A40: Chevito
...

Sheet Ranking
A2: Naki | B2: =(stats!$B$93*10+COUNTIF(playoffs!E:E,"*K*")*10+COUNTIF(playoffs!B:B,"K")*25+COUNTIF(playoffs!C:C,"K")*20+COUNTIF(playoffs!E:E,"K*")*30+(stats!$B$95/250)-COUNTIF(playoffs!D:D,"K")*15)/('partidos regular'!$B$1-43) -> 5.8709412
A3: Emily | B3: =(stats!$B$2*10+COUNTIF(playoffs!E:E,"*E*")*10+COUNTIF(playoffs!B:B,"E")*25+COUNTIF(playoffs!C:C,"E")*20+COUNTIF(playoffs!E:E,"E*")*30+(stats!$B$4/250)-COUNTIF(playoffs!D:D,"E")*15)/('partidos regular'!$B$1) -> 6.5943559
A4: Juany | B4: =(stats!$B$15*10+COUNTIF(playoffs!E:E,"*J*")*10+COUNTIF(playoffs!B:B,"J")*25+COUNTIF(playoffs!C:C,"J")*20+COUNTIF(playoffs!E:E,"J*")*30+(stats!B17/250)-COUNTIF(playoffs!D:D,"J")*15)/('partidos regular'!$B$1) -> 8.6387596
A5: Latuf | B5: =(stats!$B$28*10+COUNTIF(playoffs!E:E,"*L*")*10+COUNTIF(playoffs!B:B,"L")*25+COUNTIF(playoffs!C:C,"L")*20+COUNTIF(playoffs!E:E,"L*")*30+(stats!$B$30/250)-COUNTIF(playoffs!D:D,"L")*15)/('partidos regular'!$B$1) -> 6.9194363
A6: Scrava | B6: =(stats!$B$67*10+COUNTIF(playoffs!E:E,"*S*")*10+COUNTIF(playoffs!B:B,"S")*25+COUNTIF(playoffs!C:C,"S")*20+COUNTIF(playoffs!E:E,"S*")*30+(stats!B69/250)-COUNTIF(playoffs!D:D,"S")*15)/('partidos regular'!$B$1) -> 6.3747873
A7: Nehue | B7: =(stats!$B$80*10+COUNTIF(playoffs!E:E,"*N*")*10+COUNTIF(playoffs!B:B,"N")*25+COUNTIF(playoffs!C:C,"N")*20+COUNTIF(playoffs!E:E,"N*")*30+(stats!B82/250)-COUNTIF(playoffs!D:D,"N")*15)/('partidos regular'!$B$1) -> 5.8613406
A8: Gaspe | B8: =(stats!$B$54*10+COUNTIF(playoffs!E:E,"*G*")*10+COUNTIF(playoffs!B:B,"G")*25+COUNTIF(playoffs!C:C,"G")*20+COUNTIF(playoffs!E:E,"G*")*30+(stats!B56/250)-COUNTIF(playoffs!D:D,"G")*15)/('partidos regular'!$B$1) -> 6.5615267
A9: Chevito | B9: =(stats!$B$41*10+COUNTIF(playoffs!E:E,"*C*")*10+COUNTIF(playoffs!B:B,"C")*25+COUNTIF(playoffs!C:C,"C")*20+COUNTIF(playoffs!E:E,"C*")*30+(stats!B43/250)-COUNTIF(playoffs!D:D,"C")*15)/(('partidos regular'!$B$1)-14) -> 5.5195441

Sheet paternidades
A1: Emily
A2: e-g | B2: =COUNTIF('partidos regular'!A:A,"EG")+COUNTIF(playoffs!A:A,"EG")+COUNTIF(playoffs!E:E,"EG")&"-"&COUNTIF('partidos regular'!A:A,"GE")+COUNTIF(playoffs!A:A,"GE")+COUNTIF(playoffs!E:E,"GE")&" ("&COUNTIF(playoffs!A:A,"EG")+COUNTIF(playoffs!E:E,"EG")&"-"&COUNTIF(playoffs!A:A,"GE")+COUNTIF(playoffs!E:E,"GE")&")" -> 9-6 (0-0)
A3: e-s | B3: =COUNTIF('partidos regular'!A:A,"ES")+COUNTIF(playoffs!A:A,"ES")+COUNTIF(playoffs!E:E,"ES")&"-"&COUNTIF('partidos regular'!A:A,"SE")+COUNTIF(playoffs!A:A,"SE")+COUNTIF(playoffs!E:E,"SE")&" ("&COUNTIF(playoffs!A:A,"ES")+COUNTIF(playoffs!E:E,"ES")&"-"&COUNTIF(playoffs!A:A,"SE")+COUNTIF(playoffs!E:E,"SE")&")" -> 6-9 (0-1)
A4: e-n | B4: =COUNTIF('partidos regular'!A:A,"EN")+COUNTIF(playoffs!A:A,"EN")+COUNTIF(playoffs!E:E,"EN")&"-"&COUNTIF('partidos regular'!A:A,"NE")+COUNTIF(playoffs!A:A,"NE")+COUNTIF(playoffs!E:E,"GE")&" ("&COUNTIF(playoffs!A:A,"EN")+COUNTIF(playoffs!E:E,"EN")&"-"&COUNTIF(playoffs!A:A,"NE")+COUNTIF(playoffs!E:E,"NE")&")" -> 9-6 (0-0)
A5: e-l | B5: =COUNTIF('partidos regular'!A:A,"EL")+COUNTIF(playoffs!A:A,"EL")+COUNTIF(playoffs!E:E,"EL")&"-"&COUNTIF('partidos regular'!A:A,"LE")+COUNTIF(playoffs!A:A,"LE")+COUNTIF(playoffs!E:E,"LE")&" ("&COUNTIF(playoffs!A:A,"EL")+COUNTIF(playoffs!E:E,"EL")&"-"&COUNTIF(playoffs!A:A,"LE")+COUNTIF(playoffs!E:E,"LE")&")" -> 9-6 (0-0)
A6: e-c | B6: =COUNTIF('partidos regular'!A:A,"EC")+COUNTIF(playoffs!A:A,"EC")+COUNTIF(playoffs!E:E,"EC")&"-"&COUNTIF('partidos regular'!A:A,"CE")+COUNTIF(playoffs!A:A,"CE")+COUNTIF(playoffs!E:E,"CE")&" ("&COUNTIF(playoffs!A:A,"EC")+COUNTIF(playoffs!E:E,"EC")&"-"&COUNTIF(playoffs!A:A,"CE")+COUNTIF(playoffs!E:E,"CE")&")" -> 5-9 (0-0)
A7: e-k | B7: =COUNTIF('partidos regular'!A:A,"EK")+COUNTIF(playoffs!A:A,"EK")+COUNTIF(playoffs!E:E,"EK")&"-"&COUNTIF('partidos regular'!A:A,"KE")+COUNTIF(playoffs!A:A,"KE")+COUNTIF(playoffs!E:E,"KE")&" ("&COUNTIF(playoffs!A:A,"EK")+COUNTIF(playoffs!E:E,"EK")&"-"&COUNTIF(playoffs!A:A,"KE")+COUNTIF(playoffs!E:E,"KE")&")" -> 5-8 (1-0)
A8: e-j | B8: =COUNTIF('partidos regular'!A:A,"EJ")+COUNTIF(playoffs!A:A,"EJ")+COUNTIF(playoffs!E:E,"EJ")&"-"&COUNTIF('partidos regular'!A:A,"JE")+COUNTIF(playoffs!A:A,"JE")+COUNTIF(playoffs!E:E,"JE")&" ("&COUNTIF(playoffs!A:A,"EJ")+COUNTIF(playoffs!E:E,"EJ")&"-"&COUNTIF(playoffs!A:A,"JE")+COUNTIF(playoffs!E:E,"JE")&")" -> 9-8 (1-1)
A9: Relleno
A10: Relleno
A11: Gaspe
A12: g-e | B12: =COUNTIF('partidos regular'!A:A,"GE")+COUNTIF(playoffs!A:A,"GE")+COUNTIF(playoffs!E:E,"GE")&"-"&COUNTIF('partidos regular'!A:A,"EG")+COUNTIF(playoffs!A:A,"EG")+COUNTIF(playoffs!E:E,"EG")&" ("&COUNTIF(playoffs!A:A,"GE")+COUNTIF(playoffs!E:E,"GE")&"-"&COUNTIF(playoffs!A:A,"EG")+COUNTIF(playoffs!E:E,"EG")&")" -> 6-9 (0-0)
A13: g-s | B13: =COUNTIF('partidos regular'!A:A,"GS")+COUNTIF(playoffs!A:A,"GS")+COUNTIF(playoffs!E:E,"GS")&"-"&COUNTIF('partidos regular'!A:A,"SG")+COUNTIF(playoffs!A:A,"SG")+COUNTIF(playoffs!E:E,"SG")&" ("&COUNTIF(playoffs!A:A,"GS")+COUNTIF(playoffs!E:E,"GS")&"-"&COUNTIF(playoffs!A:A,"SG")+COUNTIF(playoffs!E:E,"SG")&")" -> 10-6 (1-0)
A14: g-n | B14: =COUNTIF('partidos regular'!A:A,"GN")+COUNTIF(playoffs!A:A,"GN")+COUNTIF(playoffs!E:E,"GN")&"-"&COUNTIF('partidos regular'!A:A,"NG")+COUNTIF(playoffs!A:A,"NG")+COUNTIF(playoffs!E:E,"NG")&" ("&COUNTIF(playoffs!A:A,"GN")+COUNTIF(playoffs!E:E,"GN")&"-"&COUNTIF(playoffs!A:A,"NG")+COUNTIF(playoffs!E:E,"NG")&")" -> 10-11 (1-0)
A15: g-l | B15: =COUNTIF('partidos regular'!A:A,"GL")+COUNTIF(playoffs!A:A,"GL")+COUNTIF(playoffs!E:E,"GL")&"-"&COUNTIF('partidos regular'!A:A,"LG")+COUNTIF(playoffs!A:A,"LG")+COUNTIF(playoffs!E:E,"LG")&" ("&COUNTIF(playoffs!A:A,"GL")+COUNTIF(playoffs!E:E,"GL")&"-"&COUNTIF(playoffs!A:A,"LG")+COUNTIF(playoffs!E:E,"LG")&")" -> 10-6 (0-1)
A16: g-c | B16: =COUNTIF('partidos regular'!A:A,"GC")+COUNTIF(playoffs!A:A,"GC")+COUNTIF(playoffs!E:E,"GC")&"-"&COUNTIF('partidos regular'!A:A,"CG")+COUNTIF(playoffs!A:A,"CG")+COUNTIF(playoffs!E:E,"CG")&" ("&COUNTIF(playoffs!A:A,"GC")+COUNTIF(playoffs!E:E,"GC")&"-"&COUNTIF(playoffs!A:A,"CG")+COUNTIF(playoffs!E:E,"CG")&")" -> 5-7 (0-0)
A17: g-k | B17: =COUNTIF('partidos regular'!A:A,"GK")+COUNTIF(playoffs!A:A,"GK")+COUNTIF(playoffs!E:E,"GK")&"-"&COUNTIF('partidos regular'!A:A,"KG")+COUNTIF(playoffs!A:A,"KG")+COUNTIF(playoffs!E:E,"KG")&" ("&COUNTIF(playoffs!A:A,"GK")+COUNTIF(playoffs!E:E,"GK")&"-"&COUNTIF(playoffs!A:A,"KG")+COUNTIF(playoffs!E:E,"KG")&")" -> 7-2 (0-0)
A18: g-j | B18: =COUNTIF('partidos regular'!A:A,"GJ")+COUNTIF(playoffs!A:A,"GJ")+COUNTIF(playoffs!E:E,"GJ")&"-"&COUNTIF('partidos regular'!A:A,"JG")+COUNTIF(playoffs!A:A,"JG")+COUNTIF(playoffs!E:E,"JG")&" ("&COUNTIF(playoffs!A:A,"GJ")+COUNTIF(playoffs!E:E,"GJ")&"-"&COUNTIF(playoffs!A:A,"JG")+COUNTIF(playoffs!E:E,"JG")&")" -> 5-13 (1-2)
A19: Relleno
A20: Relleno
A21: Scrava
A22: s-e | B22: =COUNTIF('partidos regular'!A:A,"SE")+COUNTIF(playoffs!A:A,"SE")+COUNTIF(playoffs!E:E,"SE")&"-"&COUNTIF('partidos regular'!A:A,"ES")+COUNTIF(playoffs!A:A,"ES")+COUNTIF(playoffs!E:E,"ES")&" ("&COUNTIF(playoffs!A:A,"SE")+COUNTIF(playoffs!E:E,"SE")&"-"&COUNTIF(playoffs!A:A,"ES")+COUNTIF(playoffs!E:E,"ES")&")" -> 9-6 (1-0)
A23: s-g | B23: =COUNTIF('partidos regular'!A:A,"SG")+COUNTIF(playoffs!A:A,"SG")+COUNTIF(playoffs!E:E,"SG")&"-"&COUNTIF('partidos regular'!A:A,"GS")+COUNTIF(playoffs!A:A,"GS")+COUNTIF(playoffs!E:E,"GS")&" ("&COUNTIF(playoffs!A:A,"SG")+COUNTIF(playoffs!E:E,"SG")&"-"&COUNTIF(playoffs!A:A,"GS")+COUNTIF(playoffs!E:E,"GS")&")" -> 6-10 (0-1)
A24: s-n | B24: =COUNTIF('partidos regular'!A:A,"SN")+COUNTIF(playoffs!A:A,"SN")+COUNTIF(playoffs!E:E,"SN")&"-"&COUNTIF('partidos regular'!A:A,"NS")+COUNTIF(playoffs!A:A,"NS")+COUNTIF(playoffs!E:E,"NS")&" ("&COUNTIF(playoffs!A:A,"SN")+COUNTIF(playoffs!E:E,"SN")&"-"&COUNTIF(playoffs!A:A,"NS")+COUNTIF(playoffs!E:E,"NS")&")" -> 6-9 (0-0)
A25: s-l | B25: =COUNTIF('partidos regular'!A:A,"SL")+COUNTIF(playoffs!A:A,"SL")+COUNTIF(playoffs!E:E,"SL")&"-"&COUNTIF('partidos regular'!A:A,"LS")+COUNTIF(playoffs!A:A,"LS")+COUNTIF(playoffs!E:E,"LS")&" ("&COUNTIF(playoffs!A:A,"SL")+COUNTIF(playoffs!E:E,"SL")&"-"&COUNTIF(playoffs!A:A,"LS")+COUNTIF(playoffs!E:E,"LS")&")" -> 9-9 (1-1)
A26: s-c | B26: =COUNTIF('partidos regular'!A:A,"SC")+COUNTIF(playoffs!A:A,"SC")+COUNTIF(playoffs!E:E,"SC")&"-"&COUNTIF('partidos regular'!A:A,"CS")+COUNTIF(playoffs!A:A,"CS")+COUNTIF(playoffs!E:E,"CS")&" ("&COUNTIF(playoffs!A:A,"SC")+COUNTIF(playoffs!E:E,"SC")&"-"&COUNTIF(playoffs!A:A,"CS")+COUNTIF(playoffs!E:E,"CS")&")" -> 7-6 (0-0)
A27: s-k | B27: =COUNTIF('partidos regular'!A:A,"SK")+COUNTIF(playoffs!A:A,"SK")+COUNTIF(playoffs!E:E,"SK")&"-"&COUNTIF('partidos regular'!A:A,"KS")+COUNTIF(playoffs!A:A,"KS")+COUNTIF(playoffs!E:E,"KS")&" ("&COUNTIF(playoffs!A:A,"SK")+COUNTIF(playoffs!E:E,"SK")&"-"&COUNTIF(playoffs!A:A,"KS")+COUNTIF(playoffs!E:E,"KS")&")" -> 5-4 (0-0)
A28: s-j | B28: =COUNTIF('partidos regular'!A:A,"SJ")+COUNTIF(playoffs!A:A,"SJ")+COUNTIF(playoffs!E:E,"SJ")&"-"&COUNTIF('partidos regular'!A:A,"JS")+COUNTIF(playoffs!A:A,"JS")+COUNTIF(playoffs!E:E,"JS")&" ("&COUNTIF(playoffs!A:A,"SJ")+COUNTIF(playoffs!E:E,"SJ")&"-"&COUNTIF(playoffs!A:A,"JS")+COUNTIF(playoffs!E:E,"JS")&")" -> 9-11 (0-1)
A29: Relleno
A30: Relleno
A31: Nehue
A32: n-e | B32: =COUNTIF('partidos regular'!A:A,"NE")+COUNTIF(playoffs!A:A,"NE")+COUNTIF(playoffs!E:E,"NE")&"-"&COUNTIF('partidos regular'!A:A,"EN")+COUNTIF(playoffs!A:A,"EN")+COUNTIF(playoffs!E:E,"EN")&" ("&COUNTIF(playoffs!A:A,"NE")+COUNTIF(playoffs!E:E,"NE")&"-"&COUNTIF(playoffs!A:A,"EN")+COUNTIF(playoffs!E:E,"EN")&")" -> 6-9 (0-0)
A33: n-g | B33: =COUNTIF('partidos regular'!A:A,"NG")+COUNTIF(playoffs!A:A,"NG")+COUNTIF(playoffs!E:E,"NG")&"-"&COUNTIF('partidos regular'!A:A,"GN")+COUNTIF(playoffs!A:A,"GN")+COUNTIF(playoffs!E:E,"GN")&" ("&COUNTIF(playoffs!A:A,"NG")+COUNTIF(playoffs!E:E,"NG")&"-"&COUNTIF(playoffs!A:A,"GN")+COUNTIF(playoffs!E:E,"GN")&")" -> 11-10 (0-1)
A34: n-s | B34: =COUNTIF('partidos regular'!A:A,"NS")+COUNTIF(playoffs!A:A,"NS")+COUNTIF(playoffs!E:E,"NS")&"-"&COUNTIF('partidos regular'!A:A,"SN")+COUNTIF(playoffs!A:A,"SN")+COUNTIF(playoffs!E:E,"SN")&" ("&COUNTIF(playoffs!A:A,"NS")+COUNTIF(playoffs!E:E,"NS")&"-"&COUNTIF(playoffs!A:A,"SN")+COUNTIF(playoffs!E:E,"SN")&")" -> 9-6 (0-0)
A35: n-l | B35: =COUNTIF('partidos regular'!A:A,"NL")+COUNTIF(playoffs!A:A,"NL")+COUNTIF(playoffs!E:E,"NL")&"-"&COUNTIF('partidos regular'!A:A,"LN")+COUNTIF(playoffs!A:A,"LN")+COUNTIF(playoffs!E:E,"LN")&" ("&COUNTIF(playoffs!A:A,"NL")+COUNTIF(playoffs!E:E,"NL")&"-"&COUNTIF(playoffs!A:A,"LN")+COUNTIF(playoffs!E:E,"LN")&")" -> 3-11 (0-0)
A36: n-c | B36: =COUNTIF('partidos regular'!A:A,"NC")+COUNTIF(playoffs!A:A,"NC")+COUNTIF(playoffs!E:E,"NC")&"-"&COUNTIF('partidos regular'!A:A,"CN")+COUNTIF(playoffs!A:A,"CN")+COUNTIF(playoffs!E:E,"CN")&" ("&COUNTIF(playoffs!A:A,"NC")+COUNTIF(playoffs!E:E,"NC")&"-"&COUNTIF(playoffs!A:A,"CN")+COUNTIF(playoffs!E:E,"CN")&")" -> 8-6 (1-0)
A37: n-k | B37: =COUNTIF('partidos regular'!A:A,"NK")+COUNTIF(playoffs!A:A,"NK")+COUNTIF(playoffs!E:E,"NK")&"-"&COUNTIF('partidos regular'!A:A,"KN")+COUNTIF(playoffs!A:A,"KN")+COUNTIF(playoffs!E:E,"KN")&" ("&COUNTIF(playoffs!A:A,"NK")+COUNTIF(playoffs!E:E,"NK")&"-"&COUNTIF(playoffs!A:A,"KN")+COUNTIF(playoffs!E:E,"KN")&")" -> 3-6 (0-1)
A38: n-j | B38: =COUNTIF('partidos regular'!A:A,"NJ")+COUNTIF(playoffs!A:A,"NJ")+COUNTIF(playoffs!E:E,"NJ")&"-"&COUNTIF('partidos regular'!A:A,"JN")+COUNTIF(playoffs!A:A,"JN")+COUNTIF(playoffs!E:E,"JN")&" ("&COUNTIF(playoffs!A:A,"NJ")+COUNTIF(playoffs!E:E,"NJ")&"-"&COUNTIF(playoffs!A:A,"JN")+COUNTIF(playoffs!E:E,"JN")&")" -> 8-8 (0-1)
A39: Relleno
A40: Relleno
...
